class AppError extends Error {
  constructor(message, statusCode) {
    super(message);
    this.statusCode = statusCode;
    this.status = `${statusCode}`.startsWith('4') ? 'fail' : 'error';
    this.isOperational = true;

    Error.captureStackTrace(this, this.constructor);
  }
}

class NotFoundError extends AppError {
  constructor(message = 'Resource not found') {
    super(message, 404);
  }
}

class BadRequestError extends AppError {
  constructor(message = 'Bad request') {
    super(message, 400);
  }
}

class UnauthorizedError extends AppError {
  constructor(message = 'Unauthorized access') {
    super(message, 401);
  }
}

class ForbiddenError extends AppError {
  constructor(message = 'Forbidden access') {
    super(message, 403);
  }
}

class ConflictError extends AppError {
  constructor(message = 'Resource conflict') {
    super(message, 409);
  }
}

// Function to handle errors in async functions
const catchAsync = (fn) => {
  return (req, res, next) => {
    fn(req, res, next).catch(next);
  };
};

export {
  AppError,
  NotFoundError,
  BadRequestError,
  UnauthorizedError,
  ForbiddenError,
  ConflictError,
  catchAsync
};

